Workbook
Name reconciliation_base: reconciliation_base!$A$1:$O$4001

Sheet Executive Summary
A1: EXECUTIVE SUMMARY: REVENUE RECONCILIATION ANALYSIS
A3: DATASET OVERVIEW | H3: KEY DRIVERS OF VARIANCE
A4: Metric | B4: Value | C4: Context | H4: Issue Type | I4: Occurrences | J4: Total Variance | K4: % of Variance
A5: Total Orders Analyzed | B5: =COUNTA(reconciliation_base!A:A)-1 -> 4000 | C5: 2-year period (2023-2024) | H5: #1 Unit Mismatch | I5: =COUNTIF(reconciliation_base!Q:Q,1) -> 197 | J5: =SUMIF(reconciliation_base!Q:Q,1,reconciliation_base!Z:Z) -> 363390.07 | K5: =J5/SUM(reconciliation_base!Z:Z) -> 0.98888958
A6: Total Billed Revenue | B6: =SUM(reconciliation_base!X:X) -> 2.5436576e+08 | C6: Gross billing amount | H6: #2 List Price Mismatch | I6: =COUNTIF(reconciliation_base!R:R,1) -> 123 | J6: =SUMIF(reconciliation_base!R:R,1,reconciliation_base!Z:Z) -> 36253.367 | K6: =J6/SUM(reconciliation_base!Z:Z) -> 0.098655905
A7: Net Revenue Variance | B7: =SUM(reconciliation_base!Z:Z) -> 367472.85 | C7: Overbilled vs Expected | H7: #3 Late Return | I7: =COUNTIF(reconciliation_base!U:U,1) -> 191 | J7: =SUMIF(reconciliation_base!U:U,1,reconciliation_base!Z:Z) -> 28457.737 | K7: =J7/SUM(reconciliation_base!Z:Z) -> 0.077441741
A8: Variance as % of Revenue | B8: =SUM(reconciliation_base!Z:Z)/SUM(reconciliation_base!X:X) -> 0.0014446632 | C8: Impact ratio | H8: #4 Contract Price Mismatch | I8: =COUNTIF(reconciliation_base!S:S,1) -> 7 | J8: =SUMIF(reconciliation_base!S:S,1,reconciliation_base!Z:Z) -> 7438.176 | K8: =J8/SUM(reconciliation_base!Z:Z) -> 0.02024143
A9: Orders with Issues (FAIL) | B9: =COUNTIF(reconciliation_base!W:W,"FAIL") -> 503 | C9: Orders requiring attention | H9: #5 Expired Contract | I9: =COUNTIF(reconciliation_base!T:T,1) -> 5 | J9: =SUMIF(reconciliation_base!T:T,1,reconciliation_base!Z:Z) -> 7438.176 | K9: =J9/SUM(reconciliation_base!Z:Z) -> 0.02024143
A10: Clean Orders (PASS) | B10: =COUNTIF(reconciliation_base!W:W,"PASS") -> 3497 | C10: Successfully reconciled | H10: #6 Over Return | I10: =COUNTIF(reconciliation_base!V:V,1) -> 15 | J10: =SUMIF(reconciliation_base!V:V,1,reconciliation_base!Z:Z) -> 3979.4256 | K10: =J10/SUM(reconciliation_base!Z:Z) -> 0.010829169
A11: Issue Rate | B11: =COUNTIF(reconciliation_base!W:W,"FAIL")/(COUNTA(reconciliation_base!W:W)-1) -> 0.12575 | C11: % of orders with problems
H12: YEAR-OVER-YEAR TREND
A13: FINANCIAL IMPACT SUMMARY | H13: Year | I13: Total Variance | J13: Order Count | K13: Variance/Order
A14: Category | B14: Amount | C14: % of Total | D14: Interpretation | H14: 2023 | I14: =SUMIFS(reconciliation_base!Z:Z,reconciliation_base!AC:AC,"2023-*") -> 190266.38 | J14: =COUNTIF(reconciliation_base!AC:AC,"2023-*") -> 2003 | K14: =IF(I14>0,H14/I14,0) -> 0.010632462
A15: Total Overbilling (Positive Variance) | B15: =SUMIF(reconciliation_base!Z:Z,">0") -> 493353.97 | C15: =B15/(ABS(B15)+ABS(B16)) -> 0.79671514 | D15: Revenue billed above expected | H15: 2024 | I15: =SUMIFS(reconciliation_base!Z:Z,reconciliation_base!AC:AC,"2024-*") -> 177206.47 | J15: =COUNTIF(reconciliation_base!AC:AC,"2024-*") -> 1997 | K15: =IF(I15>0,H15/I15,0) -> 0.011421705
A16: Total Underbilling (Negative Variance) | B16: =SUMIF(reconciliation_base!Z:Z,"<0") -> -125881.12 | C16: =ABS(B16)/(ABS(B15)+ABS(B16)) -> 0.20328486 | D16: Revenue shortfall | H16: YoY Change | I16: =H15-H14 -> 1 | J16: =I15-I14 -> -13059.91 | K16: =J15-J14 -> -6
A17: Net Position | B17: =SUM(reconciliation_base!Z:Z) -> 367472.85 | C17: =B17/(ABS(B15)+ABS(B16)) -> 0.59343027 | D17: Net overbilling amount | H17: YoY % Change | I17: =IF(H14<>0,(H15-H14)/H14,0) -> 0.00049431537 | K17: =IF(J14<>0,(J15-J14)/J14,0) -> -0.0029955067
A18: Average Variance per Issue Order | B18: =AVERAGEIF(reconciliation_base!Z:Z,"<>0") -> 1185.3963 | D18: Per-order impact
A19: Maximum Single Order Variance | B19: =MAX(reconciliation_base!Z:Z) -> 12319.933 | D19: Largest overbilling | H19: ANOMALY DETECTED
A20: Minimum Single Order Variance | B20: =MIN(reconciliation_base!Z:Z) -> -6159.9665 | D20: Largest underbilling | H20: Month | I20: 45078
H21: Variance | I21: =SUMIFS(reconciliation_base!Z:Z,reconciliation_base!AC:AC,"2023-06") -> 43272.064
A22: RISK PROFILE | H22: Status | I22: HIGH SPIKE - Z-Score +2.68
A23: Risk Level | B23: Order Count | C23: % of Orders | D23: Total Variance | E23: Avg Variance | F23: Financial Exposure | H23: Action | I23: Investigation Required
A24: HIGH | B24: =COUNTIF(reconciliation_base!AB:AB,"HIGH") -> 181 | C24: =B24/(COUNTA(reconciliation_base!AB:AB)-1) -> 0.04525 | D24: =SUMIF(reconciliation_base!AB:AB,"HIGH",reconciliation_base!Z:Z) -> 361776.8 | E24: =IF(B24>0,D24/B24,0) -> 1998.7668 | F24: CRITICAL - Immediate attention
A25: MEDIUM | B25: =COUNTIF(reconciliation_base!AB:AB,"MEDIUM") -> 322 | C25: =B25/(COUNTA(reconciliation_base!AB:AB)-1) -> 0.0805 | D25: =SUMIF(reconciliation_base!AB:AB,"MEDIUM",reconciliation_base!Z:Z) -> 5696.0552 | E25: =IF(B25>0,D25/B25,0) -> 17.689612 | F25: MODERATE - Review recommended | H25: RECOMMENDED ACTIONS
A26: LOW | B26: =COUNTIF(reconciliation_base!AB:AB,"LOW") -> 3497 | C26: =B26/(COUNTA(reconciliation_base!AB:AB)-1) -> 0.87425 | D26: =SUMIF(reconciliation_base!AB:AB,"LOW",reconciliation_base!Z:Z) -> 0 | E26: =IF(B26>0,D26/B26,0) -> 0 | F26: MINIMAL - Normal operations | H26: PRIORITY 1: Address Unit Mismatch Root Cause
A27: TOTAL | B27: =SUM(B24:B26) -> 4000 | C27: =SUM(C24:C26) -> 1 | D27: =SUM(D24:D26) -> 367472.85 | E27: =IF(B27>0,D27/B27,0) -> 91.868213 | H27: - Audit order entry vs billing systems
H28: - Implement unit validation controls
A29: KEY FINDINGS
A30: FINDING #1: UNIT MISMATCH IS THE DOMINANT DRIVER | H30: PRIORITY 2: Customer-Specific Review
A31: • Unit mismatches account for ~99% of total revenue variance | H31: - Contact top 10 variance customers
A32: • 197 occurrences generating $363K+ in billing discrepancies | H32: - Review for potential refund exposure
A33: • 87.8% of unit mismatches result in HIGH risk classification
H34: PRIORITY 3: Process Controls
A35: FINDING #2: SYSTEMATIC OVERBILLING PATTERN | H35: - Automate reconciliation checks
A36: • Net position shows consistent overbilling across all months | H36: - Flag orders before billing
A37: • 67% of unit mismatches result in overbilling (vs 33% underbilling)
A38: • All 24 months analyzed show net positive variance | H38: PRIORITY 4: Investigation
H39: - Investigate June 2023 anomaly
A40: FINDING #3: IMPROVING TREND | H40: - Review HIGH risk order patterns
A41: • Late returns decreased 71% year-over-year (148 to 43)
...

Sheet Total Revenue Variance
A3: Sum of revenue_variance
A4: 367472.85

Sheet reconciliation_base
A1: Order_ID | B1: Order_Date | C1: Customer_ID | D1: Product_ID | E1: ordered_units | F1: Invoice_ID | G1: Billed_Units | H1: Billed_Price | I1: total_returned_units | J1: last_return_date | K1: Contract_Price | L1: Start_Date | M1: End_Date | N1: List_Price | O1: Effective_Date | P1: missing_invoice | Q1: unit_mismatch | R1: list_price_mismatch | S1: contract_price_mismatch | T1: expired_contract | U1: late_return | V1: over_return | W1: recon_status | X1: billed_revenue | Y1: expected_revenue | Z1: revenue_variance | AA1: severity_score | AB1: risk_level | AC1: month
A2: ORD00001 | B2: 45239 | C2: CUST0281 | D2: PROD031 | E2: 26 | F2: INV00001 | G2: 26 | H2: 446.4905 | N2: 446.4905 | O2: 45161 | P2: =IF(AND(NOT(ISBLANK(ReconciliationData[[#This Row],[Contract_Price]])),ReconciliationData[[#This Row],[Billed_Price]]<>ReconciliationData[[#This Row],[Contract_Price]]),1,0) -> 0 | Q2: =IF(AND(NOT(ISBLANK(ReconciliationData[[#This Row],[Billed_Units]])),ReconciliationData[[#This Row],[ordered_units]]<>ReconciliationData[[#This Row],[Billed_Units]]),1,0) -> 0 | R2: =IF(AND(NOT(ISBLANK(ReconciliationData[[#This Row],[Billed_Price]])),NOT(ISBLANK(ReconciliationData[[#This Row],[List_Price]])),ReconciliationData[[#This Row],[Billed_Price]]<>ReconciliationData[[#This Row],[List_Price]]),1,0) -> 0 | S2: =IF(AND(NOT(ISBLANK(ReconciliationData[[#This Row],[Contract_Price]])),ReconciliationData[[#This Row],[Billed_Price]]<>ReconciliationData[[#This Row],[Contract_Price]]),1,0) -> 0 | T2: =IF(AND(NOT(ISBLANK(ReconciliationData[[#This Row],[End_Date]])),ReconciliationData[[#This Row],[Order_Date]]>ReconciliationData[[#This Row],[End_Date]]),1,0) -> 0 | U2: =IF(AND(NOT(ISBLANK(ReconciliationData[[#This Row],[last_return_date]])),ReconciliationData[[#This Row],[last_return_date]]>ReconciliationData[[#This Row],[Order_Date]]+60),1,0) -> 0 | V2: =IF(ReconciliationData[[#This Row],[total_returned_units]]>ReconciliationData[[#This Row],[ordered_units]],1,0) -> 0 | W2: =IF( OR(ReconciliationData[[#This Row],[missing_invoice]]=1, ReconciliationData[[#This Row],[unit_mismatch]]=1, ReconciliationData[[#This Row],[list_price_mismatch]]=1, ReconciliationData[[#This Row],[contract_price_mismatch]]=1, ReconciliationData[[#This Row],[expired_contract]]=1, ReconciliationData[[#This Row],[late_return]]=1, ReconciliationData[[#This Row],[over_return]]=1), "FAIL","PASS") -> PASS | X2: =ReconciliationData[[#This Row],[Billed_Units]]*ReconciliationData[[#This Row],[Billed_Price]] -> 11608.753 | Y2: =ReconciliationData[[#This Row],[ordered_units]]*ReconciliationData[[#This Row],[List_Price]] -> 11608.753 | Z2: =ReconciliationData[[#This Row],[billed_revenue]]-ReconciliationData[[#This Row],[expected_revenue]] -> 0 | AA2: =ReconciliationData[[#This Row],[missing_invoice]]*5 + ReconciliationData[[#This Row],[unit_mismatch]]*3 + ReconciliationData[[#This Row],[list_price_mismatch]]*4 + ReconciliationData[[#This Row],[contract_price_mismatch]]*4 + ReconciliationData[[#This Row],[expired_contract]]*4 + ReconciliationData[[#This Row],[late_return]]*2 + ReconciliationData[[#This Row],[over_return]]*3 + IF(ABS(ReconciliationData[[#This Row],[revenue_variance]])>500,5,0) -> 0 | AB2: =IF(ReconciliationData[[#This Row],[severity_score]]=0,"LOW", IF(ReconciliationData[[#This Row],[severity_score]]<=5,"MEDIUM","HIGH")) -> LOW | AC2: =TEXT(ReconciliationData[[#This Row],[Order_Date]],"YYYY-MM") -> 2023-11
A3: ORD00002 | B3: 45637 | C3: CUST0591 | D3: PROD252 | E3: 139 | F3: INV00002 | G3: 139 | H3: 444.22 | N3: 444.22 | O3: 45074 | P3: =IF(ISBLANK(ReconciliationData[[#This Row],[Invoice_ID]]),1,0) -> 0 | Q3: =IF(AND(NOT(ISBLANK(ReconciliationData[[#This Row],[Billed_Units]])),ReconciliationData[[#This Row],[ordered_units]]<>ReconciliationData[[#This Row],[Billed_Units]]),1,0) -> 0 | R3: =IF(AND(NOT(ISBLANK(ReconciliationData[[#This Row],[Billed_Price]])),NOT(ISBLANK(ReconciliationData[[#This Row],[List_Price]])),ReconciliationData[[#This Row],[Billed_Price]]<>ReconciliationData[[#This Row],[List_Price]]),1,0) -> 0 | S3: =IF(AND(NOT(ISBLANK(ReconciliationData[[#This Row],[Contract_Price]])),ReconciliationData[[#This Row],[Billed_Price]]<>ReconciliationData[[#This Row],[Contract_Price]]),1,0) -> 0 | T3: =IF(AND(NOT(ISBLANK(ReconciliationData[[#This Row],[End_Date]])),ReconciliationData[[#This Row],[Order_Date]]>ReconciliationData[[#This Row],[End_Date]]),1,0) -> 0 | U3: =IF(AND(NOT(ISBLANK(ReconciliationData[[#This Row],[last_return_date]])),ReconciliationData[[#This Row],[last_return_date]]>ReconciliationData[[#This Row],[Order_Date]]+60),1,0) -> 0 | V3: =IF(ReconciliationData[[#This Row],[total_returned_units]]>ReconciliationData[[#This Row],[ordered_units]],1,0) -> 0 | W3: =IF( OR(ReconciliationData[[#This Row],[missing_invoice]]=1, ReconciliationData[[#This Row],[unit_mismatch]]=1, ReconciliationData[[#This Row],[list_price_mismatch]]=1, ReconciliationData[[#This Row],[contract_price_mismatch]]=1, ReconciliationData[[#This Row],[expired_contract]]=1, ReconciliationData[[#This Row],[late_return]]=1, ReconciliationData[[#This Row],[over_return]]=1), "FAIL","PASS") -> PASS | X3: =ReconciliationData[[#This Row],[Billed_Units]]*ReconciliationData[[#This Row],[Billed_Price]] -> 61746.58 | Y3: =ReconciliationData[[#This Row],[ordered_units]]*ReconciliationData[[#This Row],[List_Price]] -> 61746.58 | Z3: =ReconciliationData[[#This Row],[billed_revenue]]-ReconciliationData[[#This Row],[expected_revenue]] -> 0 | AA3: =ReconciliationData[[#This Row],[missing_invoice]]*5 + ReconciliationData[[#This Row],[unit_mismatch]]*3 + ReconciliationData[[#This Row],[list_price_mismatch]]*4 + ReconciliationData[[#This Row],[contract_price_mismatch]]*4 + ReconciliationData[[#This Row],[expired_contract]]*4 + ReconciliationData[[#This Row],[late_return]]*2 + ReconciliationData[[#This Row],[over_return]]*3 + IF(ABS(ReconciliationData[[#This Row],[revenue_variance]])>500,5,0) -> 0 | AB3: =IF(ReconciliationData[[#This Row],[severity_score]]=0,"LOW", IF(ReconciliationData[[#This Row],[severity_score]]<=5,"MEDIUM","HIGH")) -> LOW | AC3: =TEXT(ReconciliationData[[#This Row],[Order_Date]],"YYYY-MM") -> 2024-12
A4: ORD00003 | B4: 45542 | C4: CUST0187 | D4: PROD288 | E4: 9 | F4: INV00003 | G4: 9 | H4: 189.1498 | N4: 189.1498 | O4: 45108 | P4: =IF(ISBLANK(ReconciliationData[[#This Row],[Invoice_ID]]),1,0) -> 0 | Q4: =IF(AND(NOT(ISBLANK(ReconciliationData[[#This Row],[Billed_Units]])),ReconciliationData[[#This Row],[ordered_units]]<>ReconciliationData[[#This Row],[Billed_Units]]),1,0) -> 0 | R4: =IF(AND(NOT(ISBLANK(ReconciliationData[[#This Row],[Billed_Price]])),NOT(ISBLANK(ReconciliationData[[#This Row],[List_Price]])),ReconciliationData[[#This Row],[Billed_Price]]<>ReconciliationData[[#This Row],[List_Price]]),1,0) -> 0 | S4: =IF(AND(NOT(ISBLANK(ReconciliationData[[#This Row],[Contract_Price]])),ReconciliationData[[#This Row],[Billed_Price]]<>ReconciliationData[[#This Row],[Contract_Price]]),1,0) -> 0 | T4: =IF(AND(NOT(ISBLANK(ReconciliationData[[#This Row],[End_Date]])),ReconciliationData[[#This Row],[Order_Date]]>ReconciliationData[[#This Row],[End_Date]]),1,0) -> 0 | U4: =IF(AND(NOT(ISBLANK(ReconciliationData[[#This Row],[last_return_date]])),ReconciliationData[[#This Row],[last_return_date]]>ReconciliationData[[#This Row],[Order_Date]]+60),1,0) -> 0 | V4: =IF(ReconciliationData[[#This Row],[total_returned_units]]>ReconciliationData[[#This Row],[ordered_units]],1,0) -> 0 | W4: =IF( OR(ReconciliationData[[#This Row],[missing_invoice]]=1, ReconciliationData[[#This Row],[unit_mismatch]]=1, ReconciliationData[[#This Row],[list_price_mismatch]]=1, ReconciliationData[[#This Row],[contract_price_mismatch]]=1, ReconciliationData[[#This Row],[expired_contract]]=1, ReconciliationData[[#This Row],[late_return]]=1, ReconciliationData[[#This Row],[over_return]]=1), "FAIL","PASS") -> PASS | X4: =ReconciliationData[[#This Row],[Billed_Units]]*ReconciliationData[[#This Row],[Billed_Price]] -> 1702.3482 | Y4: =ReconciliationData[[#This Row],[ordered_units]]*ReconciliationData[[#This Row],[List_Price]] -> 1702.3482 | Z4: =ReconciliationData[[#This Row],[billed_revenue]]-ReconciliationData[[#This Row],[expected_revenue]] -> 0 | AA4: =ReconciliationData[[#This Row],[missing_invoice]]*5 + ReconciliationData[[#This Row],[unit_mismatch]]*3 + ReconciliationData[[#This Row],[list_price_mismatch]]*4 + ReconciliationData[[#This Row],[contract_price_mismatch]]*4 + ReconciliationData[[#This Row],[expired_contract]]*4 + ReconciliationData[[#This Row],[late_return]]*2 + ReconciliationData[[#This Row],[over_return]]*3 + IF(ABS(ReconciliationData[[#This Row],[revenue_variance]])>500,5,0) -> 0 | AB4: =IF(ReconciliationData[[#This Row],[severity_score]]=0,"LOW", IF(ReconciliationData[[#This Row],[severity_score]]<=5,"MEDIUM","HIGH")) -> LOW | AC4: =TEXT(ReconciliationData[[#This Row],[Order_Date]],"YYYY-MM") -> 2024-09
A5: ORD00004 | B5: 45334 | C5: CUST0442 | D5: PROD145 | E5: 185 | F5: INV00004 | G5: 185 | H5: 849.4395 | I5: 15 | J5: 45428 | N5: 849.4395 | O5: 45114 | P5: =IF(ISBLANK(ReconciliationData[[#This Row],[Invoice_ID]]),1,0) -> 0 | Q5: =IF(AND(NOT(ISBLANK(ReconciliationData[[#This Row],[Billed_Units]])),ReconciliationData[[#This Row],[ordered_units]]<>ReconciliationData[[#This Row],[Billed_Units]]),1,0) -> 0 | R5: =IF(AND(NOT(ISBLANK(ReconciliationData[[#This Row],[Billed_Price]])),NOT(ISBLANK(ReconciliationData[[#This Row],[List_Price]])),ReconciliationData[[#This Row],[Billed_Price]]<>ReconciliationData[[#This Row],[List_Price]]),1,0) -> 0 | S5: =IF(AND(NOT(ISBLANK(ReconciliationData[[#This Row],[Contract_Price]])),ReconciliationData[[#This Row],[Billed_Price]]<>ReconciliationData[[#This Row],[Contract_Price]]),1,0) -> 0 | T5: =IF(AND(NOT(ISBLANK(ReconciliationData[[#This Row],[End_Date]])),ReconciliationData[[#This Row],[Order_Date]]>ReconciliationData[[#This Row],[End_Date]]),1,0) -> 0 | U5: =IF(AND(NOT(ISBLANK(ReconciliationData[[#This Row],[last_return_date]])),ReconciliationData[[#This Row],[last_return_date]]>ReconciliationData[[#This Row],[Order_Date]]+60),1,0) -> 1 | V5: =IF(ReconciliationData[[#This Row],[total_returned_units]]>ReconciliationData[[#This Row],[ordered_units]],1,0) -> 0 | W5: =IF( OR(ReconciliationData[[#This Row],[missing_invoice]]=1, ReconciliationData[[#This Row],[unit_mismatch]]=1, ReconciliationData[[#This Row],[list_price_mismatch]]=1, ReconciliationData[[#This Row],[contract_price_mismatch]]=1, ReconciliationData[[#This Row],[expired_contract]]=1, ReconciliationData[[#This Row],[late_return]]=1, ReconciliationData[[#This Row],[over_return]]=1), "FAIL","PASS") -> FAIL | X5: =ReconciliationData[[#This Row],[Billed_Units]]*ReconciliationData[[#This Row],[Billed_Price]] -> 157146.31 | Y5: =ReconciliationData[[#This Row],[ordered_units]]*ReconciliationData[[#This Row],[List_Price]] -> 157146.31 | Z5: =ReconciliationData[[#This Row],[billed_revenue]]-ReconciliationData[[#This Row],[expected_revenue]] -> 0 | AA5: =ReconciliationData[[#This Row],[missing_invoice]]*5 + ReconciliationData[[#This Row],[unit_mismatch]]*3 + ReconciliationData[[#This Row],[list_price_mismatch]]*4 + ReconciliationData[[#This Row],[contract_price_mismatch]]*4 + ReconciliationData[[#This Row],[expired_contract]]*4 + ReconciliationData[[#This Row],[late_return]]*2 + ReconciliationData[[#This Row],[over_return]]*3 + IF(ABS(ReconciliationData[[#This Row],[revenue_variance]])>500,5,0) -> 2 | AB5: =IF(ReconciliationData[[#This Row],[severity_score]]=0,"LOW", IF(ReconciliationData[[#This Row],[severity_score]]<=5,"MEDIUM","HIGH")) -> MEDIUM | AC5: =TEXT(ReconciliationData[[#This Row],[Order_Date]],"YYYY-MM") -> 2024-02
A6: ORD00005 | B6: 45598 | C6: CUST0010 | D6: PROD088 | E6: 192 | F6: INV00005 | G6: 192 | H6: 353.5272 | I6: 18 | J6: 45450 | N6: 353.5272 | O6: 45182 | P6: =IF(ISBLANK(ReconciliationData[[#This Row],[Invoice_ID]]),1,0) -> 0 | Q6: =IF(AND(NOT(ISBLANK(ReconciliationData[[#This Row],[Billed_Units]])),ReconciliationData[[#This Row],[ordered_units]]<>ReconciliationData[[#This Row],[Billed_Units]]),1,0) -> 0 | R6: =IF(AND(NOT(ISBLANK(ReconciliationData[[#This Row],[Billed_Price]])),NOT(ISBLANK(ReconciliationData[[#This Row],[List_Price]])),ReconciliationData[[#This Row],[Billed_Price]]<>ReconciliationData[[#This Row],[List_Price]]),1,0) -> 0 | S6: =IF(AND(NOT(ISBLANK(ReconciliationData[[#This Row],[Contract_Price]])),ReconciliationData[[#This Row],[Billed_Price]]<>ReconciliationData[[#This Row],[Contract_Price]]),1,0) -> 0 | T6: =IF(AND(NOT(ISBLANK(ReconciliationData[[#This Row],[End_Date]])),ReconciliationData[[#This Row],[Order_Date]]>ReconciliationData[[#This Row],[End_Date]]),1,0) -> 0 | U6: =IF(AND(NOT(ISBLANK(ReconciliationData[[#This Row],[last_return_date]])),ReconciliationData[[#This Row],[last_return_date]]>ReconciliationData[[#This Row],[Order_Date]]+60),1,0) -> 0 | V6: =IF(ReconciliationData[[#This Row],[total_returned_units]]>ReconciliationData[[#This Row],[ordered_units]],1,0) -> 0 | W6: =IF( OR(ReconciliationData[[#This Row],[missing_invoice]]=1, ReconciliationData[[#This Row],[unit_mismatch]]=1, ReconciliationData[[#This Row],[list_price_mismatch]]=1, ReconciliationData[[#This Row],[contract_price_mismatch]]=1, ReconciliationData[[#This Row],[expired_contract]]=1, ReconciliationData[[#This Row],[late_return]]=1, ReconciliationData[[#This Row],[over_return]]=1), "FAIL","PASS") -> PASS | X6: =ReconciliationData[[#This Row],[Billed_Units]]*ReconciliationData[[#This Row],[Billed_Price]] -> 67877.222 | Y6: =ReconciliationData[[#This Row],[ordered_units]]*ReconciliationData[[#This Row],[List_Price]] -> 67877.222 | Z6: =ReconciliationData[[#This Row],[billed_revenue]]-ReconciliationData[[#This Row],[expected_revenue]] -> 0 | AA6: =ReconciliationData[[#This Row],[missing_invoice]]*5 + ReconciliationData[[#This Row],[unit_mismatch]]*3 + ReconciliationData[[#This Row],[list_price_mismatch]]*4 + ReconciliationData[[#This Row],[contract_price_mismatch]]*4 + ReconciliationData[[#This Row],[expired_contract]]*4 + ReconciliationData[[#This Row],[late_return]]*2 + ReconciliationData[[#This Row],[over_return]]*3 + IF(ABS(ReconciliationData[[#This Row],[revenue_variance]])>500,5,0) -> 0 | AB6: =IF(ReconciliationData[[#This Row],[severity_score]]=0,"LOW", IF(ReconciliationData[[#This Row],[severity_score]]<=5,"MEDIUM","HIGH")) -> LOW | AC6: =TEXT(ReconciliationData[[#This Row],[Order_Date]],"YYYY-MM") -> 2024-11
A7: ORD00006 | B7: 45570 | C7: CUST0658 | D7: PROD214 | E7: 38 | F7: INV00006 | G7: 38 | H7: 1058.35 | N7: 1058.35 | O7: 45136 | P7: =IF(ISBLANK(ReconciliationData[[#This Row],[Invoice_ID]]),1,0) -> 0 | Q7: =IF(AND(NOT(ISBLANK(ReconciliationData[[#This Row],[Billed_Units]])),ReconciliationData[[#This Row],[ordered_units]]<>ReconciliationData[[#This Row],[Billed_Units]]),1,0) -> 0 | R7: =IF(AND(NOT(ISBLANK(ReconciliationData[[#This Row],[Billed_Price]])),NOT(ISBLANK(ReconciliationData[[#This Row],[List_Price]])),ReconciliationData[[#This Row],[Billed_Price]]<>ReconciliationData[[#This Row],[List_Price]]),1,0) -> 0 | S7: =IF(AND(NOT(ISBLANK(ReconciliationData[[#This Row],[Contract_Price]])),ReconciliationData[[#This Row],[Billed_Price]]<>ReconciliationData[[#This Row],[Contract_Price]]),1,0) -> 0 | T7: =IF(AND(NOT(ISBLANK(ReconciliationData[[#This Row],[End_Date]])),ReconciliationData[[#This Row],[Order_Date]]>ReconciliationData[[#This Row],[End_Date]]),1,0) -> 0 | U7: =IF(AND(NOT(ISBLANK(ReconciliationData[[#This Row],[last_return_date]])),ReconciliationData[[#This Row],[last_return_date]]>ReconciliationData[[#This Row],[Order_Date]]+60),1,0) -> 0 | V7: =IF(ReconciliationData[[#This Row],[total_returned_units]]>ReconciliationData[[#This Row],[ordered_units]],1,0) -> 0 | W7: =IF( OR(ReconciliationData[[#This Row],[missing_invoice]]=1, ReconciliationData[[#This Row],[unit_mismatch]]=1, ReconciliationData[[#This Row],[list_price_mismatch]]=1, ReconciliationData[[#This Row],[contract_price_mismatch]]=1, ReconciliationData[[#This Row],[expired_contract]]=1, ReconciliationData[[#This Row],[late_return]]=1, ReconciliationData[[#This Row],[over_return]]=1), "FAIL","PASS") -> PASS | X7: =ReconciliationData[[#This Row],[Billed_Units]]*ReconciliationData[[#This Row],[Billed_Price]] -> 40217.3 | Y7: =ReconciliationData[[#This Row],[ordered_units]]*ReconciliationData[[#This Row],[List_Price]] -> 40217.3 | Z7: =ReconciliationData[[#This Row],[billed_revenue]]-ReconciliationData[[#This Row],[expected_revenue]] -> 0 | AA7: =ReconciliationData[[#This Row],[missing_invoice]]*5 + ReconciliationData[[#This Row],[unit_mismatch]]*3 + ReconciliationData[[#This Row],[list_price_mismatch]]*4 + ReconciliationData[[#This Row],[contract_price_mismatch]]*4 + ReconciliationData[[#This Row],[expired_contract]]*4 + ReconciliationData[[#This Row],[late_return]]*2 + ReconciliationData[[#This Row],[over_return]]*3 + IF(ABS(ReconciliationData[[#This Row],[revenue_variance]])>500,5,0) -> 0 | AB7: =IF(ReconciliationData[[#This Row],[severity_score]]=0,"LOW", IF(ReconciliationData[[#This Row],[severity_score]]<=5,"MEDIUM","HIGH")) -> LOW | AC7: =TEXT(ReconciliationData[[#This Row],[Order_Date]],"YYYY-MM") -> 2024-10
A8: ORD00007 | B8: 45612 | C8: CUST0056 | D8: PROD279 | E8: 144 | F8: INV00007 | G8: 144 | H8: 700.9356 | I8: 4 | J8: 45293 | N8: 700.9356 | O8: 45077 | P8: =IF(ISBLANK(ReconciliationData[[#This Row],[Invoice_ID]]),1,0) -> 0 | Q8: =IF(AND(NOT(ISBLANK(ReconciliationData[[#This Row],[Billed_Units]])),ReconciliationData[[#This Row],[ordered_units]]<>ReconciliationData[[#This Row],[Billed_Units]]),1,0) -> 0 | R8: =IF(AND(NOT(ISBLANK(ReconciliationData[[#This Row],[Billed_Price]])),NOT(ISBLANK(ReconciliationData[[#This Row],[List_Price]])),ReconciliationData[[#This Row],[Billed_Price]]<>ReconciliationData[[#This Row],[List_Price]]),1,0) -> 0 | S8: =IF(AND(NOT(ISBLANK(ReconciliationData[[#This Row],[Contract_Price]])),ReconciliationData[[#This Row],[Billed_Price]]<>ReconciliationData[[#This Row],[Contract_Price]]),1,0) -> 0 | T8: =IF(AND(NOT(ISBLANK(ReconciliationData[[#This Row],[End_Date]])),ReconciliationData[[#This Row],[Order_Date]]>ReconciliationData[[#This Row],[End_Date]]),1,0) -> 0 | U8: =IF(AND(NOT(ISBLANK(ReconciliationData[[#This Row],[last_return_date]])),ReconciliationData[[#This Row],[last_return_date]]>ReconciliationData[[#This Row],[Order_Date]]+60),1,0) -> 0 | V8: =IF(ReconciliationData[[#This Row],[total_returned_units]]>ReconciliationData[[#This Row],[ordered_units]],1,0) -> 0 | W8: =IF( OR(ReconciliationData[[#This Row],[missing_invoice]]=1, ReconciliationData[[#This Row],[unit_mismatch]]=1, ReconciliationData[[#This Row],[list_price_mismatch]]=1, ReconciliationData[[#This Row],[contract_price_mismatch]]=1, ReconciliationData[[#This Row],[expired_contract]]=1, ReconciliationData[[#This Row],[late_return]]=1, ReconciliationData[[#This Row],[over_return]]=1), "FAIL","PASS") -> PASS | X8: =ReconciliationData[[#This Row],[Billed_Units]]*ReconciliationData[[#This Row],[Billed_Price]] -> 100934.73 | Y8: =ReconciliationData[[#This Row],[ordered_units]]*ReconciliationData[[#This Row],[List_Price]] -> 100934.73 | Z8: =ReconciliationData[[#This Row],[billed_revenue]]-ReconciliationData[[#This Row],[expected_revenue]] -> 0 | AA8: =ReconciliationData[[#This Row],[missing_invoice]]*5 + ReconciliationData[[#This Row],[unit_mismatch]]*3 + ReconciliationData[[#This Row],[list_price_mismatch]]*4 + ReconciliationData[[#This Row],[contract_price_mismatch]]*4 + ReconciliationData[[#This Row],[expired_contract]]*4 + ReconciliationData[[#This Row],[late_return]]*2 + ReconciliationData[[#This Row],[over_return]]*3 + IF(ABS(ReconciliationData[[#This Row],[revenue_variance]])>500,5,0) -> 0 | AB8: =IF(ReconciliationData[[#This Row],[severity_score]]=0,"LOW", IF(ReconciliationData[[#This Row],[severity_score]]<=5,"MEDIUM","HIGH")) -> LOW | AC8: =TEXT(ReconciliationData[[#This Row],[Order_Date]],"YYYY-MM") -> 2024-11
A9: ORD00008 | B9: 45366 | C9: CUST0799 | D9: PROD083 | E9: 172 | F9: INV00008 | G9: 169 | H9: 510.9184 | N9: 510.9184 | O9: 44981 | P9: =IF(ISBLANK(ReconciliationData[[#This Row],[Invoice_ID]]),1,0) -> 0 | Q9: =IF(AND(NOT(ISBLANK(ReconciliationData[[#This Row],[Billed_Units]])),ReconciliationData[[#This Row],[ordered_units]]<>ReconciliationData[[#This Row],[Billed_Units]]),1,0) -> 1 | R9: =IF(AND(NOT(ISBLANK(ReconciliationData[[#This Row],[Billed_Price]])),NOT(ISBLANK(ReconciliationData[[#This Row],[List_Price]])),ReconciliationData[[#This Row],[Billed_Price]]<>ReconciliationData[[#This Row],[List_Price]]),1,0) -> 0 | S9: =IF(AND(NOT(ISBLANK(ReconciliationData[[#This Row],[Contract_Price]])),ReconciliationData[[#This Row],[Billed_Price]]<>ReconciliationData[[#This Row],[Contract_Price]]),1,0) -> 0 | T9: =IF(AND(NOT(ISBLANK(ReconciliationData[[#This Row],[End_Date]])),ReconciliationData[[#This Row],[Order_Date]]>ReconciliationData[[#This Row],[End_Date]]),1,0) -> 0 | U9: =IF(AND(NOT(ISBLANK(ReconciliationData[[#This Row],[last_return_date]])),ReconciliationData[[#This Row],[last_return_date]]>ReconciliationData[[#This Row],[Order_Date]]+60),1,0) -> 0 | V9: =IF(ReconciliationData[[#This Row],[total_returned_units]]>ReconciliationData[[#This Row],[ordered_units]],1,0) -> 0 | W9: =IF( OR(ReconciliationData[[#This Row],[missing_invoice]]=1, ReconciliationData[[#This Row],[unit_mismatch]]=1, ReconciliationData[[#This Row],[list_price_mismatch]]=1, ReconciliationData[[#This Row],[contract_price_mismatch]]=1, ReconciliationData[[#This Row],[expired_contract]]=1, ReconciliationData[[#This Row],[late_return]]=1, ReconciliationData[[#This Row],[over_return]]=1), "FAIL","PASS") -> FAIL | X9: =ReconciliationData[[#This Row],[Billed_Units]]*ReconciliationData[[#This Row],[Billed_Price]] -> 86345.21 | Y9: =ReconciliationData[[#This Row],[ordered_units]]*ReconciliationData[[#This Row],[List_Price]] -> 87877.965 | Z9: =ReconciliationData[[#This Row],[billed_revenue]]-ReconciliationData[[#This Row],[expected_revenue]] -> -1532.7552 | AA9: =ReconciliationData[[#This Row],[missing_invoice]]*5 + ReconciliationData[[#This Row],[unit_mismatch]]*3 + ReconciliationData[[#This Row],[list_price_mismatch]]*4 + ReconciliationData[[#This Row],[contract_price_mismatch]]*4 + ReconciliationData[[#This Row],[expired_contract]]*4 + ReconciliationData[[#This Row],[late_return]]*2 + ReconciliationData[[#This Row],[over_return]]*3 + IF(ABS(ReconciliationData[[#This Row],[revenue_variance]])>500,5,0) -> 8 | AB9: =IF(ReconciliationData[[#This Row],[severity_score]]=0,"LOW", IF(ReconciliationData[[#This Row],[severity_score]]<=5,"MEDIUM","HIGH")) -> HIGH | AC9: =TEXT(ReconciliationData[[#This Row],[Order_Date]],"YYYY-MM") -> 2024-03
A10: ORD00009 | B10: 45047 | C10: CUST0180 | D10: PROD268 | E10: 15 | F10: INV00009 | G10: 15 | H10: 365.9533 | N10: 365.9533 | O10: 44824 | P10: =IF(ISBLANK(ReconciliationData[[#This Row],[Invoice_ID]]),1,0) -> 0 | Q10: =IF(AND(NOT(ISBLANK(ReconciliationData[[#This Row],[Billed_Units]])),ReconciliationData[[#This Row],[ordered_units]]<>ReconciliationData[[#This Row],[Billed_Units]]),1,0) -> 0 | R10: =IF(AND(NOT(ISBLANK(ReconciliationData[[#This Row],[Billed_Price]])),NOT(ISBLANK(ReconciliationData[[#This Row],[List_Price]])),ReconciliationData[[#This Row],[Billed_Price]]<>ReconciliationData[[#This Row],[List_Price]]),1,0) -> 0 | S10: =IF(AND(NOT(ISBLANK(ReconciliationData[[#This Row],[Contract_Price]])),ReconciliationData[[#This Row],[Billed_Price]]<>ReconciliationData[[#This Row],[Contract_Price]]),1,0) -> 0 | T10: =IF(AND(NOT(ISBLANK(ReconciliationData[[#This Row],[End_Date]])),ReconciliationData[[#This Row],[Order_Date]]>ReconciliationData[[#This Row],[End_Date]]),1,0) -> 0 | U10: =IF(AND(NOT(ISBLANK(ReconciliationData[[#This Row],[last_return_date]])),ReconciliationData[[#This Row],[last_return_date]]>ReconciliationData[[#This Row],[Order_Date]]+60),1,0) -> 0 | V10: =IF(ReconciliationData[[#This Row],[total_returned_units]]>ReconciliationData[[#This Row],[ordered_units]],1,0) -> 0 | W10: =IF( OR(ReconciliationData[[#This Row],[missing_invoice]]=1, ReconciliationData[[#This Row],[unit_mismatch]]=1, ReconciliationData[[#This Row],[list_price_mismatch]]=1, ReconciliationData[[#This Row],[contract_price_mismatch]]=1, ReconciliationData[[#This Row],[expired_contract]]=1, ReconciliationData[[#This Row],[late_return]]=1, ReconciliationData[[#This Row],[over_return]]=1), "FAIL","PASS") -> PASS | X10: =ReconciliationData[[#This Row],[Billed_Units]]*ReconciliationData[[#This Row],[Billed_Price]] -> 5489.2995 | Y10: =ReconciliationData[[#This Row],[ordered_units]]*ReconciliationData[[#This Row],[List_Price]] -> 5489.2995 | Z10: =ReconciliationData[[#This Row],[billed_revenue]]-ReconciliationData[[#This Row],[expected_revenue]] -> 0 | AA10: =ReconciliationData[[#This Row],[missing_invoice]]*5 + ReconciliationData[[#This Row],[unit_mismatch]]*3 + ReconciliationData[[#This Row],[list_price_mismatch]]*4 + ReconciliationData[[#This Row],[contract_price_mismatch]]*4 + ReconciliationData[[#This Row],[expired_contract]]*4 + ReconciliationData[[#This Row],[late_return]]*2 + ReconciliationData[[#This Row],[over_return]]*3 + IF(ABS(ReconciliationData[[#This Row],[revenue_variance]])>500,5,0) -> 0 | AB10: =IF(ReconciliationData[[#This Row],[severity_score]]=0,"LOW", IF(ReconciliationData[[#This Row],[severity_score]]<=5,"MEDIUM","HIGH")) -> LOW | AC10: =TEXT(ReconciliationData[[#This Row],[Order_Date]],"YYYY-MM") -> 2023-05
A11: ORD00010 | B11: 44945 | C11: CUST0423 | D11: PROD140 | E11: 160 | F11: INV00010 | G11: 160 | H11: 426.3788 | N11: 426.3788 | O11: 44923 | P11: =IF(ISBLANK(ReconciliationData[[#This Row],[Invoice_ID]]),1,0) -> 0 | Q11: =IF(AND(NOT(ISBLANK(ReconciliationData[[#This Row],[Billed_Units]])),ReconciliationData[[#This Row],[ordered_units]]<>ReconciliationData[[#This Row],[Billed_Units]]),1,0) -> 0 | R11: =IF(AND(NOT(ISBLANK(ReconciliationData[[#This Row],[Billed_Price]])),NOT(ISBLANK(ReconciliationData[[#This Row],[List_Price]])),ReconciliationData[[#This Row],[Billed_Price]]<>ReconciliationData[[#This Row],[List_Price]]),1,0) -> 0 | S11: =IF(AND(NOT(ISBLANK(ReconciliationData[[#This Row],[Contract_Price]])),ReconciliationData[[#This Row],[Billed_Price]]<>ReconciliationData[[#This Row],[Contract_Price]]),1,0) -> 0 | T11: =IF(AND(NOT(ISBLANK(ReconciliationData[[#This Row],[End_Date]])),ReconciliationData[[#This Row],[Order_Date]]>ReconciliationData[[#This Row],[End_Date]]),1,0) -> 0 | U11: =IF(AND(NOT(ISBLANK(ReconciliationData[[#This Row],[last_return_date]])),ReconciliationData[[#This Row],[last_return_date]]>ReconciliationData[[#This Row],[Order_Date]]+60),1,0) -> 0 | V11: =IF(ReconciliationData[[#This Row],[total_returned_units]]>ReconciliationData[[#This Row],[ordered_units]],1,0) -> 0 | W11: =IF( OR(ReconciliationData[[#This Row],[missing_invoice]]=1, ReconciliationData[[#This Row],[unit_mismatch]]=1, ReconciliationData[[#This Row],[list_price_mismatch]]=1, ReconciliationData[[#This Row],[contract_price_mismatch]]=1, ReconciliationData[[#This Row],[expired_contract]]=1, ReconciliationData[[#This Row],[late_return]]=1, ReconciliationData[[#This Row],[over_return]]=1), "FAIL","PASS") -> PASS | X11: =ReconciliationData[[#This Row],[Billed_Units]]*ReconciliationData[[#This Row],[Billed_Price]] -> 68220.608 | Y11: =ReconciliationData[[#This Row],[ordered_units]]*ReconciliationData[[#This Row],[List_Price]] -> 68220.608 | Z11: =ReconciliationData[[#This Row],[billed_revenue]]-ReconciliationData[[#This Row],[expected_revenue]] -> 0 | AA11: =ReconciliationData[[#This Row],[missing_invoice]]*5 + ReconciliationData[[#This Row],[unit_mismatch]]*3 + ReconciliationData[[#This Row],[list_price_mismatch]]*4 + ReconciliationData[[#This Row],[contract_price_mismatch]]*4 + ReconciliationData[[#This Row],[expired_contract]]*4 + ReconciliationData[[#This Row],[late_return]]*2 + ReconciliationData[[#This Row],[over_return]]*3 + IF(ABS(ReconciliationData[[#This Row],[revenue_variance]])>500,5,0) -> 0 | AB11: =IF(ReconciliationData[[#This Row],[severity_score]]=0,"LOW", IF(ReconciliationData[[#This Row],[severity_score]]<=5,"MEDIUM","HIGH")) -> LOW | AC11: =TEXT(ReconciliationData[[#This Row],[Order_Date]],"YYYY-MM") -> 2023-01
A12: ORD00011 | B12: 45647 | C12: CUST0498 | D12: PROD215 | E12: 112 | F12: INV00011 | G12: 112 | H12: 461.6928 | N12: 461.6928 | O12: 45031 | P12: =IF(ISBLANK(ReconciliationData[[#This Row],[Invoice_ID]]),1,0) -> 0 | Q12: =IF(AND(NOT(ISBLANK(ReconciliationData[[#This Row],[Billed_Units]])),ReconciliationData[[#This Row],[ordered_units]]<>ReconciliationData[[#This Row],[Billed_Units]]),1,0) -> 0 | R12: =IF(AND(NOT(ISBLANK(ReconciliationData[[#This Row],[Billed_Price]])),NOT(ISBLANK(ReconciliationData[[#This Row],[List_Price]])),ReconciliationData[[#This Row],[Billed_Price]]<>ReconciliationData[[#This Row],[List_Price]]),1,0) -> 0 | S12: =IF(AND(NOT(ISBLANK(ReconciliationData[[#This Row],[Contract_Price]])),ReconciliationData[[#This Row],[Billed_Price]]<>ReconciliationData[[#This Row],[Contract_Price]]),1,0) -> 0 | T12: =IF(AND(NOT(ISBLANK(ReconciliationData[[#This Row],[End_Date]])),ReconciliationData[[#This Row],[Order_Date]]>ReconciliationData[[#This Row],[End_Date]]),1,0) -> 0 | U12: =IF(AND(NOT(ISBLANK(ReconciliationData[[#This Row],[last_return_date]])),ReconciliationData[[#This Row],[last_return_date]]>ReconciliationData[[#This Row],[Order_Date]]+60),1,0) -> 0 | V12: =IF(ReconciliationData[[#This Row],[total_returned_units]]>ReconciliationData[[#This Row],[ordered_units]],1,0) -> 0 | W12: =IF( OR(ReconciliationData[[#This Row],[missing_invoice]]=1, ReconciliationData[[#This Row],[unit_mismatch]]=1, ReconciliationData[[#This Row],[list_price_mismatch]]=1, ReconciliationData[[#This Row],[contract_price_mismatch]]=1, ReconciliationData[[#This Row],[expired_contract]]=1, ReconciliationData[[#This Row],[late_return]]=1, ReconciliationData[[#This Row],[over_return]]=1), "FAIL","PASS") -> PASS | X12: =ReconciliationData[[#This Row],[Billed_Units]]*ReconciliationData[[#This Row],[Billed_Price]] -> 51709.594 | Y12: =ReconciliationData[[#This Row],[ordered_units]]*ReconciliationData[[#This Row],[List_Price]] -> 51709.594 | Z12: =ReconciliationData[[#This Row],[billed_revenue]]-ReconciliationData[[#This Row],[expected_revenue]] -> 0 | AA12: =ReconciliationData[[#This Row],[missing_invoice]]*5 + ReconciliationData[[#This Row],[unit_mismatch]]*3 + ReconciliationData[[#This Row],[list_price_mismatch]]*4 + ReconciliationData[[#This Row],[contract_price_mismatch]]*4 + ReconciliationData[[#This Row],[expired_contract]]*4 + ReconciliationData[[#This Row],[late_return]]*2 + ReconciliationData[[#This Row],[over_return]]*3 + IF(ABS(ReconciliationData[[#This Row],[revenue_variance]])>500,5,0) -> 0 | AB12: =IF(ReconciliationData[[#This Row],[severity_score]]=0,"LOW", IF(ReconciliationData[[#This Row],[severity_score]]<=5,"MEDIUM","HIGH")) -> LOW | AC12: =TEXT(ReconciliationData[[#This Row],[Order_Date]],"YYYY-MM") -> 2024-12
A13: ORD00012 | B13: 45394 | C13: CUST0495 | D13: PROD156 | E13: 43 | F13: INV00012 | G13: 43 | H13: 687.6584 | I13: 13 | J13: 45639 | N13: 687.6584 | O13: 45139 | P13: =IF(ISBLANK(ReconciliationData[[#This Row],[Invoice_ID]]),1,0) -> 0 | Q13: =IF(AND(NOT(ISBLANK(ReconciliationData[[#This Row],[Billed_Units]])),ReconciliationData[[#This Row],[ordered_units]]<>ReconciliationData[[#This Row],[Billed_Units]]),1,0) -> 0 | R13: =IF(AND(NOT(ISBLANK(ReconciliationData[[#This Row],[Billed_Price]])),NOT(ISBLANK(ReconciliationData[[#This Row],[List_Price]])),ReconciliationData[[#This Row],[Billed_Price]]<>ReconciliationData[[#This Row],[List_Price]]),1,0) -> 0 | S13: =IF(AND(NOT(ISBLANK(ReconciliationData[[#This Row],[Contract_Price]])),ReconciliationData[[#This Row],[Billed_Price]]<>ReconciliationData[[#This Row],[Contract_Price]]),1,0) -> 0 | T13: =IF(AND(NOT(ISBLANK(ReconciliationData[[#This Row],[End_Date]])),ReconciliationData[[#This Row],[Order_Date]]>ReconciliationData[[#This Row],[End_Date]]),1,0) -> 0 | U13: =IF(AND(NOT(ISBLANK(ReconciliationData[[#This Row],[last_return_date]])),ReconciliationData[[#This Row],[last_return_date]]>ReconciliationData[[#This Row],[Order_Date]]+60),1,0) -> 1 | V13: =IF(ReconciliationData[[#This Row],[total_returned_units]]>ReconciliationData[[#This Row],[ordered_units]],1,0) -> 0 | W13: =IF( OR(ReconciliationData[[#This Row],[missing_invoice]]=1, ReconciliationData[[#This Row],[unit_mismatch]]=1, ReconciliationData[[#This Row],[list_price_mismatch]]=1, ReconciliationData[[#This Row],[contract_price_mismatch]]=1, ReconciliationData[[#This Row],[expired_contract]]=1, ReconciliationData[[#This Row],[late_return]]=1, ReconciliationData[[#This Row],[over_return]]=1), "FAIL","PASS") -> FAIL | X13: =ReconciliationData[[#This Row],[Billed_Units]]*ReconciliationData[[#This Row],[Billed_Price]] -> 29569.311 | Y13: =ReconciliationData[[#This Row],[ordered_units]]*ReconciliationData[[#This Row],[List_Price]] -> 29569.311 | Z13: =ReconciliationData[[#This Row],[billed_revenue]]-ReconciliationData[[#This Row],[expected_revenue]] -> 0 | AA13: =ReconciliationData[[#This Row],[missing_invoice]]*5 + ReconciliationData[[#This Row],[unit_mismatch]]*3 + ReconciliationData[[#This Row],[list_price_mismatch]]*4 + ReconciliationData[[#This Row],[contract_price_mismatch]]*4 + ReconciliationData[[#This Row],[expired_contract]]*4 + ReconciliationData[[#This Row],[late_return]]*2 + ReconciliationData[[#This Row],[over_return]]*3 + IF(ABS(ReconciliationData[[#This Row],[revenue_variance]])>500,5,0) -> 2 | AB13: =IF(ReconciliationData[[#This Row],[severity_score]]=0,"LOW", IF(ReconciliationData[[#This Row],[severity_score]]<=5,"MEDIUM","HIGH")) -> MEDIUM | AC13: =TEXT(ReconciliationData[[#This Row],[Order_Date]],"YYYY-MM") -> 2024-04
A14: ORD00013 | B14: 45116 | C14: CUST0610 | D14: PROD246 | E14: 178 | F14: INV00013 | G14: 178 | H14: 725.5032 | N14: 725.5032 | O14: 44858 | P14: =IF(ISBLANK(ReconciliationData[[#This Row],[Invoice_ID]]),1,0) -> 0 | Q14: =IF(AND(NOT(ISBLANK(ReconciliationData[[#This Row],[Billed_Units]])),ReconciliationData[[#This Row],[ordered_units]]<>ReconciliationData[[#This Row],[Billed_Units]]),1,0) -> 0 | R14: =IF(AND(NOT(ISBLANK(ReconciliationData[[#This Row],[Billed_Price]])),NOT(ISBLANK(ReconciliationData[[#This Row],[List_Price]])),ReconciliationData[[#This Row],[Billed_Price]]<>ReconciliationData[[#This Row],[List_Price]]),1,0) -> 0 | S14: =IF(AND(NOT(ISBLANK(ReconciliationData[[#This Row],[Contract_Price]])),ReconciliationData[[#This Row],[Billed_Price]]<>ReconciliationData[[#This Row],[Contract_Price]]),1,0) -> 0 | T14: =IF(AND(NOT(ISBLANK(ReconciliationData[[#This Row],[End_Date]])),ReconciliationData[[#This Row],[Order_Date]]>ReconciliationData[[#This Row],[End_Date]]),1,0) -> 0 | U14: =IF(AND(NOT(ISBLANK(ReconciliationData[[#This Row],[last_return_date]])),ReconciliationData[[#This Row],[last_return_date]]>ReconciliationData[[#This Row],[Order_Date]]+60),1,0) -> 0 | V14: =IF(ReconciliationData[[#This Row],[total_returned_units]]>ReconciliationData[[#This Row],[ordered_units]],1,0) -> 0 | W14: =IF( OR(ReconciliationData[[#This Row],[missing_invoice]]=1, ReconciliationData[[#This Row],[unit_mismatch]]=1, ReconciliationData[[#This Row],[list_price_mismatch]]=1, ReconciliationData[[#This Row],[contract_price_mismatch]]=1, ReconciliationData[[#This Row],[expired_contract]]=1, ReconciliationData[[#This Row],[late_return]]=1, ReconciliationData[[#This Row],[over_return]]=1), "FAIL","PASS") -> PASS | X14: =ReconciliationData[[#This Row],[Billed_Units]]*ReconciliationData[[#This Row],[Billed_Price]] -> 129139.57 | Y14: =ReconciliationData[[#This Row],[ordered_units]]*ReconciliationData[[#This Row],[List_Price]] -> 129139.57 | Z14: =ReconciliationData[[#This Row],[billed_revenue]]-ReconciliationData[[#This Row],[expected_revenue]] -> 0 | AA14: =ReconciliationData[[#This Row],[missing_invoice]]*5 + ReconciliationData[[#This Row],[unit_mismatch]]*3 + ReconciliationData[[#This Row],[list_price_mismatch]]*4 + ReconciliationData[[#This Row],[contract_price_mismatch]]*4 + ReconciliationData[[#This Row],[expired_contract]]*4 + ReconciliationData[[#This Row],[late_return]]*2 + ReconciliationData[[#This Row],[over_return]]*3 + IF(ABS(ReconciliationData[[#This Row],[revenue_variance]])>500,5,0) -> 0 | AB14: =IF(ReconciliationData[[#This Row],[severity_score]]=0,"LOW", IF(ReconciliationData[[#This Row],[severity_score]]<=5,"MEDIUM","HIGH")) -> LOW | AC14: =TEXT(ReconciliationData[[#This Row],[Order_Date]],"YYYY-MM") -> 2023-07
A15: ORD00014 | B15: 44971 | C15: CUST0447 | D15: PROD199 | E15: 79 | F15: INV00014 | G15: 79 | H15: 248.2445 | N15: 248.2445 | O15: 44933 | P15: =IF(ISBLANK(ReconciliationData[[#This Row],[Invoice_ID]]),1,0) -> 0 | Q15: =IF(AND(NOT(ISBLANK(ReconciliationData[[#This Row],[Billed_Units]])),ReconciliationData[[#This Row],[ordered_units]]<>ReconciliationData[[#This Row],[Billed_Units]]),1,0) -> 0 | R15: =IF(AND(NOT(ISBLANK(ReconciliationData[[#This Row],[Billed_Price]])),NOT(ISBLANK(ReconciliationData[[#This Row],[List_Price]])),ReconciliationData[[#This Row],[Billed_Price]]<>ReconciliationData[[#This Row],[List_Price]]),1,0) -> 0 | S15: =IF(AND(NOT(ISBLANK(ReconciliationData[[#This Row],[Contract_Price]])),ReconciliationData[[#This Row],[Billed_Price]]<>ReconciliationData[[#This Row],[Contract_Price]]),1,0) -> 0 | T15: =IF(AND(NOT(ISBLANK(ReconciliationData[[#This Row],[End_Date]])),ReconciliationData[[#This Row],[Order_Date]]>ReconciliationData[[#This Row],[End_Date]]),1,0) -> 0 | U15: =IF(AND(NOT(ISBLANK(ReconciliationData[[#This Row],[last_return_date]])),ReconciliationData[[#This Row],[last_return_date]]>ReconciliationData[[#This Row],[Order_Date]]+60),1,0) -> 0 | V15: =IF(ReconciliationData[[#This Row],[total_returned_units]]>ReconciliationData[[#This Row],[ordered_units]],1,0) -> 0 | W15: =IF( OR(ReconciliationData[[#This Row],[missing_invoice]]=1, ReconciliationData[[#This Row],[unit_mismatch]]=1, ReconciliationData[[#This Row],[list_price_mismatch]]=1, ReconciliationData[[#This Row],[contract_price_mismatch]]=1, ReconciliationData[[#This Row],[expired_contract]]=1, ReconciliationData[[#This Row],[late_return]]=1, ReconciliationData[[#This Row],[over_return]]=1), "FAIL","PASS") -> PASS | X15: =ReconciliationData[[#This Row],[Billed_Units]]*ReconciliationData[[#This Row],[Billed_Price]] -> 19611.316 | Y15: =ReconciliationData[[#This Row],[ordered_units]]*ReconciliationData[[#This Row],[List_Price]] -> 19611.316 | Z15: =ReconciliationData[[#This Row],[billed_revenue]]-ReconciliationData[[#This Row],[expected_revenue]] -> 0 | AA15: =ReconciliationData[[#This Row],[missing_invoice]]*5 + ReconciliationData[[#This Row],[unit_mismatch]]*3 + ReconciliationData[[#This Row],[list_price_mismatch]]*4 + ReconciliationData[[#This Row],[contract_price_mismatch]]*4 + ReconciliationData[[#This Row],[expired_contract]]*4 + ReconciliationData[[#This Row],[late_return]]*2 + ReconciliationData[[#This Row],[over_return]]*3 + IF(ABS(ReconciliationData[[#This Row],[revenue_variance]])>500,5,0) -> 0 | AB15: =IF(ReconciliationData[[#This Row],[severity_score]]=0,"LOW", IF(ReconciliationData[[#This Row],[severity_score]]<=5,"MEDIUM","HIGH")) -> LOW | AC15: =TEXT(ReconciliationData[[#This Row],[Order_Date]],"YYYY-MM") -> 2023-02
A16: ORD00015 | B16: 45563 | C16: CUST0133 | D16: PROD115 | E16: 143 | F16: INV00015 | G16: 143 | H16: 265.4496 | N16: 265.4496 | O16: 44999 | P16: =IF(ISBLANK(ReconciliationData[[#This Row],[Invoice_ID]]),1,0) -> 0 | Q16: =IF(AND(NOT(ISBLANK(ReconciliationData[[#This Row],[Billed_Units]])),ReconciliationData[[#This Row],[ordered_units]]<>ReconciliationData[[#This Row],[Billed_Units]]),1,0) -> 0 | R16: =IF(AND(NOT(ISBLANK(ReconciliationData[[#This Row],[Billed_Price]])),NOT(ISBLANK(ReconciliationData[[#This Row],[List_Price]])),ReconciliationData[[#This Row],[Billed_Price]]<>ReconciliationData[[#This Row],[List_Price]]),1,0) -> 0 | S16: =IF(AND(NOT(ISBLANK(ReconciliationData[[#This Row],[Contract_Price]])),ReconciliationData[[#This Row],[Billed_Price]]<>ReconciliationData[[#This Row],[Contract_Price]]),1,0) -> 0 | T16: =IF(AND(NOT(ISBLANK(ReconciliationData[[#This Row],[End_Date]])),ReconciliationData[[#This Row],[Order_Date]]>ReconciliationData[[#This Row],[End_Date]]),1,0) -> 0 | U16: =IF(AND(NOT(ISBLANK(ReconciliationData[[#This Row],[last_return_date]])),ReconciliationData[[#This Row],[last_return_date]]>ReconciliationData[[#This Row],[Order_Date]]+60),1,0) -> 0 | V16: =IF(ReconciliationData[[#This Row],[total_returned_units]]>ReconciliationData[[#This Row],[ordered_units]],1,0) -> 0 | W16: =IF( OR(ReconciliationData[[#This Row],[missing_invoice]]=1, ReconciliationData[[#This Row],[unit_mismatch]]=1, ReconciliationData[[#This Row],[list_price_mismatch]]=1, ReconciliationData[[#This Row],[contract_price_mismatch]]=1, ReconciliationData[[#This Row],[expired_contract]]=1, ReconciliationData[[#This Row],[late_return]]=1, ReconciliationData[[#This Row],[over_return]]=1), "FAIL","PASS") -> PASS | X16: =ReconciliationData[[#This Row],[Billed_Units]]*ReconciliationData[[#This Row],[Billed_Price]] -> 37959.293 | Y16: =ReconciliationData[[#This Row],[ordered_units]]*ReconciliationData[[#This Row],[List_Price]] -> 37959.293 | Z16: =ReconciliationData[[#This Row],[billed_revenue]]-ReconciliationData[[#This Row],[expected_revenue]] -> 0 | AA16: =ReconciliationData[[#This Row],[missing_invoice]]*5 + ReconciliationData[[#This Row],[unit_mismatch]]*3 + ReconciliationData[[#This Row],[list_price_mismatch]]*4 + ReconciliationData[[#This Row],[contract_price_mismatch]]*4 + ReconciliationData[[#This Row],[expired_contract]]*4 + ReconciliationData[[#This Row],[late_return]]*2 + ReconciliationData[[#This Row],[over_return]]*3 + IF(ABS(ReconciliationData[[#This Row],[revenue_variance]])>500,5,0) -> 0 | AB16: =IF(ReconciliationData[[#This Row],[severity_score]]=0,"LOW", IF(ReconciliationData[[#This Row],[severity_score]]<=5,"MEDIUM","HIGH")) -> LOW | AC16: =TEXT(ReconciliationData[[#This Row],[Order_Date]],"YYYY-MM") -> 2024-09
A17: ORD00016 | B17: 45158 | C17: CUST0286 | D17: PROD003 | E17: 83 | F17: INV00016 | G17: 83 | H17: 1039.0536 | N17: 1039.0536 | O17: 45054 | P17: =IF(ISBLANK(ReconciliationData[[#This Row],[Invoice_ID]]),1,0) -> 0 | Q17: =IF(AND(NOT(ISBLANK(ReconciliationData[[#This Row],[Billed_Units]])),ReconciliationData[[#This Row],[ordered_units]]<>ReconciliationData[[#This Row],[Billed_Units]]),1,0) -> 0 | R17: =IF(AND(NOT(ISBLANK(ReconciliationData[[#This Row],[Billed_Price]])),NOT(ISBLANK(ReconciliationData[[#This Row],[List_Price]])),ReconciliationData[[#This Row],[Billed_Price]]<>ReconciliationData[[#This Row],[List_Price]]),1,0) -> 0 | S17: =IF(AND(NOT(ISBLANK(ReconciliationData[[#This Row],[Contract_Price]])),ReconciliationData[[#This Row],[Billed_Price]]<>ReconciliationData[[#This Row],[Contract_Price]]),1,0) -> 0 | T17: =IF(AND(NOT(ISBLANK(ReconciliationData[[#This Row],[End_Date]])),ReconciliationData[[#This Row],[Order_Date]]>ReconciliationData[[#This Row],[End_Date]]),1,0) -> 0 | U17: =IF(AND(NOT(ISBLANK(ReconciliationData[[#This Row],[last_return_date]])),ReconciliationData[[#This Row],[last_return_date]]>ReconciliationData[[#This Row],[Order_Date]]+60),1,0) -> 0 | V17: =IF(ReconciliationData[[#This Row],[total_returned_units]]>ReconciliationData[[#This Row],[ordered_units]],1,0) -> 0 | W17: =IF( OR(ReconciliationData[[#This Row],[missing_invoice]]=1, ReconciliationData[[#This Row],[unit_mismatch]]=1, ReconciliationData[[#This Row],[list_price_mismatch]]=1, ReconciliationData[[#This Row],[contract_price_mismatch]]=1, ReconciliationData[[#This Row],[expired_contract]]=1, ReconciliationData[[#This Row],[late_return]]=1, ReconciliationData[[#This Row],[over_return]]=1), "FAIL","PASS") -> PASS | X17: =ReconciliationData[[#This Row],[Billed_Units]]*ReconciliationData[[#This Row],[Billed_Price]] -> 86241.449 | Y17: =ReconciliationData[[#This Row],[ordered_units]]*ReconciliationData[[#This Row],[List_Price]] -> 86241.449 | Z17: =ReconciliationData[[#This Row],[billed_revenue]]-ReconciliationData[[#This Row],[expected_revenue]] -> 0 | AA17: =ReconciliationData[[#This Row],[missing_invoice]]*5 + ReconciliationData[[#This Row],[unit_mismatch]]*3 + ReconciliationData[[#This Row],[list_price_mismatch]]*4 + ReconciliationData[[#This Row],[contract_price_mismatch]]*4 + ReconciliationData[[#This Row],[expired_contract]]*4 + ReconciliationData[[#This Row],[late_return]]*2 + ReconciliationData[[#This Row],[over_return]]*3 + IF(ABS(ReconciliationData[[#This Row],[revenue_variance]])>500,5,0) -> 0 | AB17: =IF(ReconciliationData[[#This Row],[severity_score]]=0,"LOW", IF(ReconciliationData[[#This Row],[severity_score]]<=5,"MEDIUM","HIGH")) -> LOW | AC17: =TEXT(ReconciliationData[[#This Row],[Order_Date]],"YYYY-MM") -> 2023-08
A18: ORD00017 | B18: 45357 | C18: CUST0304 | D18: PROD057 | E18: 27 | F18: INV00017 | G18: 27 | H18: 78.6961 | N18: 78.6961 | O18: 45083 | P18: =IF(ISBLANK(ReconciliationData[[#This Row],[Invoice_ID]]),1,0) -> 0 | Q18: =IF(AND(NOT(ISBLANK(ReconciliationData[[#This Row],[Billed_Units]])),ReconciliationData[[#This Row],[ordered_units]]<>ReconciliationData[[#This Row],[Billed_Units]]),1,0) -> 0 | R18: =IF(AND(NOT(ISBLANK(ReconciliationData[[#This Row],[Billed_Price]])),NOT(ISBLANK(ReconciliationData[[#This Row],[List_Price]])),ReconciliationData[[#This Row],[Billed_Price]]<>ReconciliationData[[#This Row],[List_Price]]),1,0) -> 0 | S18: =IF(AND(NOT(ISBLANK(ReconciliationData[[#This Row],[Contract_Price]])),ReconciliationData[[#This Row],[Billed_Price]]<>ReconciliationData[[#This Row],[Contract_Price]]),1,0) -> 0 | T18: =IF(AND(NOT(ISBLANK(ReconciliationData[[#This Row],[End_Date]])),ReconciliationData[[#This Row],[Order_Date]]>ReconciliationData[[#This Row],[End_Date]]),1,0) -> 0 | U18: =IF(AND(NOT(ISBLANK(ReconciliationData[[#This Row],[last_return_date]])),ReconciliationData[[#This Row],[last_return_date]]>ReconciliationData[[#This Row],[Order_Date]]+60),1,0) -> 0 | V18: =IF(ReconciliationData[[#This Row],[total_returned_units]]>ReconciliationData[[#This Row],[ordered_units]],1,0) -> 0 | W18: =IF( OR(ReconciliationData[[#This Row],[missing_invoice]]=1, ReconciliationData[[#This Row],[unit_mismatch]]=1, ReconciliationData[[#This Row],[list_price_mismatch]]=1, ReconciliationData[[#This Row],[contract_price_mismatch]]=1, ReconciliationData[[#This Row],[expired_contract]]=1, ReconciliationData[[#This Row],[late_return]]=1, ReconciliationData[[#This Row],[over_return]]=1), "FAIL","PASS") -> PASS | X18: =ReconciliationData[[#This Row],[Billed_Units]]*ReconciliationData[[#This Row],[Billed_Price]] -> 2124.7947 | Y18: =ReconciliationData[[#This Row],[ordered_units]]*ReconciliationData[[#This Row],[List_Price]] -> 2124.7947 | Z18: =ReconciliationData[[#This Row],[billed_revenue]]-ReconciliationData[[#This Row],[expected_revenue]] -> 0 | AA18: =ReconciliationData[[#This Row],[missing_invoice]]*5 + ReconciliationData[[#This Row],[unit_mismatch]]*3 + ReconciliationData[[#This Row],[list_price_mismatch]]*4 + ReconciliationData[[#This Row],[contract_price_mismatch]]*4 + ReconciliationData[[#This Row],[expired_contract]]*4 + ReconciliationData[[#This Row],[late_return]]*2 + ReconciliationData[[#This Row],[over_return]]*3 + IF(ABS(ReconciliationData[[#This Row],[revenue_variance]])>500,5,0) -> 0 | AB18: =IF(ReconciliationData[[#This Row],[severity_score]]=0,"LOW", IF(ReconciliationData[[#This Row],[severity_score]]<=5,"MEDIUM","HIGH")) -> LOW | AC18: =TEXT(ReconciliationData[[#This Row],[Order_Date]],"YYYY-MM") -> 2024-03
A19: ORD00018 | B19: 45419 | C19: CUST0675 | D19: PROD024 | E19: 44 | F19: INV00018 | G19: 44 | H19: 761.504 | N19: 761.504 | O19: 45161 | P19: =IF(ISBLANK(ReconciliationData[[#This Row],[Invoice_ID]]),1,0) -> 0 | Q19: =IF(AND(NOT(ISBLANK(ReconciliationData[[#This Row],[Billed_Units]])),ReconciliationData[[#This Row],[ordered_units]]<>ReconciliationData[[#This Row],[Billed_Units]]),1,0) -> 0 | R19: =IF(AND(NOT(ISBLANK(ReconciliationData[[#This Row],[Billed_Price]])),NOT(ISBLANK(ReconciliationData[[#This Row],[List_Price]])),ReconciliationData[[#This Row],[Billed_Price]]<>ReconciliationData[[#This Row],[List_Price]]),1,0) -> 0 | S19: =IF(AND(NOT(ISBLANK(ReconciliationData[[#This Row],[Contract_Price]])),ReconciliationData[[#This Row],[Billed_Price]]<>ReconciliationData[[#This Row],[Contract_Price]]),1,0) -> 0 | T19: =IF(AND(NOT(ISBLANK(ReconciliationData[[#This Row],[End_Date]])),ReconciliationData[[#This Row],[Order_Date]]>ReconciliationData[[#This Row],[End_Date]]),1,0) -> 0 | U19: =IF(AND(NOT(ISBLANK(ReconciliationData[[#This Row],[last_return_date]])),ReconciliationData[[#This Row],[last_return_date]]>ReconciliationData[[#This Row],[Order_Date]]+60),1,0) -> 0 | V19: =IF(ReconciliationData[[#This Row],[total_returned_units]]>ReconciliationData[[#This Row],[ordered_units]],1,0) -> 0 | W19: =IF( OR(ReconciliationData[[#This Row],[missing_invoice]]=1, ReconciliationData[[#This Row],[unit_mismatch]]=1, ReconciliationData[[#This Row],[list_price_mismatch]]=1, ReconciliationData[[#This Row],[contract_price_mismatch]]=1, ReconciliationData[[#This Row],[expired_contract]]=1, ReconciliationData[[#This Row],[late_return]]=1, ReconciliationData[[#This Row],[over_return]]=1), "FAIL","PASS") -> PASS | X19: =ReconciliationData[[#This Row],[Billed_Units]]*ReconciliationData[[#This Row],[Billed_Price]] -> 33506.176 | Y19: =ReconciliationData[[#This Row],[ordered_units]]*ReconciliationData[[#This Row],[List_Price]] -> 33506.176 | Z19: =ReconciliationData[[#This Row],[billed_revenue]]-ReconciliationData[[#This Row],[expected_revenue]] -> 0 | AA19: =ReconciliationData[[#This Row],[missing_invoice]]*5 + ReconciliationData[[#This Row],[unit_mismatch]]*3 + ReconciliationData[[#This Row],[list_price_mismatch]]*4 + ReconciliationData[[#This Row],[contract_price_mismatch]]*4 + ReconciliationData[[#This Row],[expired_contract]]*4 + ReconciliationData[[#This Row],[late_return]]*2 + ReconciliationData[[#This Row],[over_return]]*3 + IF(ABS(ReconciliationData[[#This Row],[revenue_variance]])>500,5,0) -> 0 | AB19: =IF(ReconciliationData[[#This Row],[severity_score]]=0,"LOW", IF(ReconciliationData[[#This Row],[severity_score]]<=5,"MEDIUM","HIGH")) -> LOW | AC19: =TEXT(ReconciliationData[[#This Row],[Order_Date]],"YYYY-MM") -> 2024-05
A20: ORD00019 | B20: 45078 | C20: CUST0195 | D20: PROD033 | E20: 62 | F20: INV00019 | G20: 62 | H20: 361.578 | N20: 361.578 | O20: 44932 | P20: =IF(ISBLANK(ReconciliationData[[#This Row],[Invoice_ID]]),1,0) -> 0 | Q20: =IF(AND(NOT(ISBLANK(ReconciliationData[[#This Row],[Billed_Units]])),ReconciliationData[[#This Row],[ordered_units]]<>ReconciliationData[[#This Row],[Billed_Units]]),1,0) -> 0 | R20: =IF(AND(NOT(ISBLANK(ReconciliationData[[#This Row],[Billed_Price]])),NOT(ISBLANK(ReconciliationData[[#This Row],[List_Price]])),ReconciliationData[[#This Row],[Billed_Price]]<>ReconciliationData[[#This Row],[List_Price]]),1,0) -> 0 | S20: =IF(AND(NOT(ISBLANK(ReconciliationData[[#This Row],[Contract_Price]])),ReconciliationData[[#This Row],[Billed_Price]]<>ReconciliationData[[#This Row],[Contract_Price]]),1,0) -> 0 | T20: =IF(AND(NOT(ISBLANK(ReconciliationData[[#This Row],[End_Date]])),ReconciliationData[[#This Row],[Order_Date]]>ReconciliationData[[#This Row],[End_Date]]),1,0) -> 0 | U20: =IF(AND(NOT(ISBLANK(ReconciliationData[[#This Row],[last_return_date]])),ReconciliationData[[#This Row],[last_return_date]]>ReconciliationData[[#This Row],[Order_Date]]+60),1,0) -> 0 | V20: =IF(ReconciliationData[[#This Row],[total_returned_units]]>ReconciliationData[[#This Row],[ordered_units]],1,0) -> 0 | W20: =IF( OR(ReconciliationData[[#This Row],[missing_invoice]]=1, ReconciliationData[[#This Row],[unit_mismatch]]=1, ReconciliationData[[#This Row],[list_price_mismatch]]=1, ReconciliationData[[#This Row],[contract_price_mismatch]]=1, ReconciliationData[[#This Row],[expired_contract]]=1, ReconciliationData[[#This Row],[late_return]]=1, ReconciliationData[[#This Row],[over_return]]=1), "FAIL","PASS") -> PASS | X20: =ReconciliationData[[#This Row],[Billed_Units]]*ReconciliationData[[#This Row],[Billed_Price]] -> 22417.836 | Y20: =ReconciliationData[[#This Row],[ordered_units]]*ReconciliationData[[#This Row],[List_Price]] -> 22417.836 | Z20: =ReconciliationData[[#This Row],[billed_revenue]]-ReconciliationData[[#This Row],[expected_revenue]] -> 0 | AA20: =ReconciliationData[[#This Row],[missing_invoice]]*5 + ReconciliationData[[#This Row],[unit_mismatch]]*3 + ReconciliationData[[#This Row],[list_price_mismatch]]*4 + ReconciliationData[[#This Row],[contract_price_mismatch]]*4 + ReconciliationData[[#This Row],[expired_contract]]*4 + ReconciliationData[[#This Row],[late_return]]*2 + ReconciliationData[[#This Row],[over_return]]*3 + IF(ABS(ReconciliationData[[#This Row],[revenue_variance]])>500,5,0) -> 0 | AB20: =IF(ReconciliationData[[#This Row],[severity_score]]=0,"LOW", IF(ReconciliationData[[#This Row],[severity_score]]<=5,"MEDIUM","HIGH")) -> LOW | AC20: =TEXT(ReconciliationData[[#This Row],[Order_Date]],"YYYY-MM") -> 2023-06
